Traceback (most recent call last):
  File "/Users/hernando/opt/anaconda3/lib/python3.9/site-packages/jupyter_cache/executors/utils.py", line 51, in single_nb_execution
    executenb(
  File "/Users/hernando/opt/anaconda3/lib/python3.9/site-packages/nbclient/client.py", line 1204, in execute
    return NotebookClient(nb=nb, resources=resources, km=km, **kwargs).execute()
  File "/Users/hernando/opt/anaconda3/lib/python3.9/site-packages/nbclient/util.py", line 84, in wrapped
    return just_run(coro(*args, **kwargs))
  File "/Users/hernando/opt/anaconda3/lib/python3.9/site-packages/nbclient/util.py", line 62, in just_run
    return loop.run_until_complete(coro)
  File "/Users/hernando/opt/anaconda3/lib/python3.9/asyncio/base_events.py", line 647, in run_until_complete
    return future.result()
  File "/Users/hernando/opt/anaconda3/lib/python3.9/site-packages/nbclient/client.py", line 663, in async_execute
    await self.async_execute_cell(
  File "/Users/hernando/opt/anaconda3/lib/python3.9/site-packages/nbclient/client.py", line 965, in async_execute_cell
    await self._check_raise_for_error(cell, cell_index, exec_reply)
  File "/Users/hernando/opt/anaconda3/lib/python3.9/site-packages/nbclient/client.py", line 862, in _check_raise_for_error
    raise CellExecutionError.from_cell_and_msg(cell, exec_reply_content)
nbclient.exceptions.CellExecutionError: An error occurred while executing the following cell:
------------------
filename = '/data/alpha.h5'
print('Data : ', dirpath + filename)

mdata = pd.read_hdf(dirpath + filename, key = 'mc/dummy')

------------------

[0;31m---------------------------------------------------------------------------[0m
[0;31mFileNotFoundError[0m                         Traceback (most recent call last)
[0;32m/var/folders/56/_pmdccc97ljb_l3v3s6gkrxm0000gn/T/ipykernel_83313/460329597.py[0m in [0;36m<module>[0;34m[0m
[1;32m      2[0m [0mprint[0m[0;34m([0m[0;34m'Data : '[0m[0;34m,[0m [0mdirpath[0m [0;34m+[0m [0mfilename[0m[0;34m)[0m[0;34m[0m[0;34m[0m[0m
[1;32m      3[0m [0;34m[0m[0m
[0;32m----> 4[0;31m [0mmdata[0m [0;34m=[0m [0mpd[0m[0;34m.[0m[0mread_hdf[0m[0;34m([0m[0mdirpath[0m [0;34m+[0m [0mfilename[0m[0;34m,[0m [0mkey[0m [0;34m=[0m [0;34m'mc/dummy'[0m[0;34m)[0m[0;34m[0m[0;34m[0m[0m
[0m
[0;32m~/opt/anaconda3/lib/python3.9/site-packages/pandas/io/pytables.py[0m in [0;36mread_hdf[0;34m(path_or_buf, key, mode, errors, where, start, stop, columns, iterator, chunksize, **kwargs)[0m
[1;32m    425[0m [0;34m[0m[0m
[1;32m    426[0m         [0;32mif[0m [0;32mnot[0m [0mexists[0m[0;34m:[0m[0;34m[0m[0;34m[0m[0m
[0;32m--> 427[0;31m             [0;32mraise[0m [0mFileNotFoundError[0m[0;34m([0m[0;34mf"File {path_or_buf} does not exist"[0m[0;34m)[0m[0;34m[0m[0;34m[0m[0m
[0m[1;32m    428[0m [0;34m[0m[0m
[1;32m    429[0m         [0mstore[0m [0;34m=[0m [0mHDFStore[0m[0;34m([0m[0mpath_or_buf[0m[0;34m,[0m [0mmode[0m[0;34m=[0m[0mmode[0m[0;34m,[0m [0merrors[0m[0;34m=[0m[0merrors[0m[0;34m,[0m [0;34m**[0m[0mkwargs[0m[0;34m)[0m[0;34m[0m[0;34m[0m[0m

[0;31mFileNotFoundError[0m: File /Users/hernando/work/docencia/master/Fisica_Particulas/USC-Fanal-v2/data/alpha.h5 does not exist
FileNotFoundError: File /Users/hernando/work/docencia/master/Fisica_Particulas/USC-Fanal-v2/data/alpha.h5 does not exist

