Traceback (most recent call last):
  File "/Users/hernando/opt/anaconda3/lib/python3.9/site-packages/jupyter_cache/executors/utils.py", line 51, in single_nb_execution
    executenb(
  File "/Users/hernando/opt/anaconda3/lib/python3.9/site-packages/nbclient/client.py", line 1204, in execute
    return NotebookClient(nb=nb, resources=resources, km=km, **kwargs).execute()
  File "/Users/hernando/opt/anaconda3/lib/python3.9/site-packages/nbclient/util.py", line 84, in wrapped
    return just_run(coro(*args, **kwargs))
  File "/Users/hernando/opt/anaconda3/lib/python3.9/site-packages/nbclient/util.py", line 62, in just_run
    return loop.run_until_complete(coro)
  File "/Users/hernando/opt/anaconda3/lib/python3.9/asyncio/base_events.py", line 647, in run_until_complete
    return future.result()
  File "/Users/hernando/opt/anaconda3/lib/python3.9/site-packages/nbclient/client.py", line 663, in async_execute
    await self.async_execute_cell(
  File "/Users/hernando/opt/anaconda3/lib/python3.9/site-packages/nbclient/client.py", line 965, in async_execute_cell
    await self._check_raise_for_error(cell, cell_index, exec_reply)
  File "/Users/hernando/opt/anaconda3/lib/python3.9/site-packages/nbclient/client.py", line 862, in _check_raise_for_error
    raise CellExecutionError.from_cell_and_msg(cell, exec_reply_content)
nbclient.exceptions.CellExecutionError: An error occurred while executing the following cell:
------------------
collaboration = collpars.collaboration
sel_erange    = collpars.sel_erange
sel_eroi      = collpars.sel_eroi

eff_Bi_blind  = collpars.eff_Bi_blind
eff_Tl_blind  = collpars.eff_Tl_blind

eff_Bi_E      = collpars.eff_Bi_E
eff_Tl_E      = collpars.eff_Tl_E
eff_Bi_RoI    = collpars.eff_Bi_RoI
eff_Tl_RoI    = collpars.eff_Tl_RoI

print('Collaboration         : {:s}'.format(collaboration))
print('Energy range          : ({:6.3f}, {:6.3f}) MeV'.format(*sel_erange))
print('RoI    range          : ({:6.3f}, {:6.3f}) MeV'.format(*sel_eroi))
print('Bi eff in E range     : {:6.4f} %'.format(100.*eff_Bi_E))
print('Tl eff in E range     : {:6.4f} %'.format(100.*eff_Tl_E))
print('Bi eff in RoI         : {:6.4f} %'.format(100.*eff_Bi_RoI))
print('Tl eff in RoI         : {:6.4f} %'.format(100.*eff_Tl_RoI))
------------------

[0;31m---------------------------------------------------------------------------[0m
[0;31mAttributeError[0m                            Traceback (most recent call last)
[0;32m/var/folders/56/_pmdccc97ljb_l3v3s6gkrxm0000gn/T/ipykernel_33478/1764282111.py[0m in [0;36m<module>[0;34m[0m
[1;32m      3[0m [0msel_eroi[0m      [0;34m=[0m [0mcollpars[0m[0;34m.[0m[0msel_eroi[0m[0;34m[0m[0;34m[0m[0m
[1;32m      4[0m [0;34m[0m[0m
[0;32m----> 5[0;31m [0meff_Bi_blind[0m  [0;34m=[0m [0mcollpars[0m[0;34m.[0m[0meff_Bi_blind[0m[0;34m[0m[0;34m[0m[0m
[0m[1;32m      6[0m [0meff_Tl_blind[0m  [0;34m=[0m [0mcollpars[0m[0;34m.[0m[0meff_Tl_blind[0m[0;34m[0m[0;34m[0m[0m
[1;32m      7[0m [0;34m[0m[0m

[0;31mAttributeError[0m: module 'collpars' has no attribute 'eff_Bi_blind'
AttributeError: module 'collpars' has no attribute 'eff_Bi_blind'

