Traceback (most recent call last):
  File "/Users/hernando/opt/anaconda3/lib/python3.9/site-packages/jupyter_cache/executors/utils.py", line 51, in single_nb_execution
    executenb(
  File "/Users/hernando/opt/anaconda3/lib/python3.9/site-packages/nbclient/client.py", line 1204, in execute
    return NotebookClient(nb=nb, resources=resources, km=km, **kwargs).execute()
  File "/Users/hernando/opt/anaconda3/lib/python3.9/site-packages/nbclient/util.py", line 84, in wrapped
    return just_run(coro(*args, **kwargs))
  File "/Users/hernando/opt/anaconda3/lib/python3.9/site-packages/nbclient/util.py", line 62, in just_run
    return loop.run_until_complete(coro)
  File "/Users/hernando/opt/anaconda3/lib/python3.9/asyncio/base_events.py", line 647, in run_until_complete
    return future.result()
  File "/Users/hernando/opt/anaconda3/lib/python3.9/site-packages/nbclient/client.py", line 663, in async_execute
    await self.async_execute_cell(
  File "/Users/hernando/opt/anaconda3/lib/python3.9/site-packages/nbclient/client.py", line 965, in async_execute_cell
    await self._check_raise_for_error(cell, cell_index, exec_reply)
  File "/Users/hernando/opt/anaconda3/lib/python3.9/site-packages/nbclient/client.py", line 862, in _check_raise_for_error
    raise CellExecutionError.from_cell_and_msg(cell, exec_reply_content)
nbclient.exceptions.CellExecutionError: An error occurred while executing the following cell:
------------------
# number of  blind events
nevts_bkg_roi  = (collpars.nevts_Bi_RoI , collpars.nevts_Tl_RoI)
unevts_bkg_roi = (collpars.unevts_Bi_RoI, collpars.unevts_Tl_RoI)
nbkg_roi       = np.sum(nevts_bkg_roi)
unbkg_roi      = np.sqrt(np.sum([u**2 for u in unevts_bkg_roi]))
for i, name in enumerate(tsamples[1:]):
    print('Number of bkg events in RoI : {:s}  = {:6.2f} +- {:6.2f}.'.format(tsamples[i+1],
                                                                            nevts_bkg_roi[i], unevts_bkg_roi[i]))
print('Total Number of bkg events in RoI = {:6.2f} +- {:6.2f}.'.format(nbkg_roi, unbkg_roi))
------------------

[0;31m---------------------------------------------------------------------------[0m
[0;31mAttributeError[0m                            Traceback (most recent call last)
[0;32m/var/folders/56/_pmdccc97ljb_l3v3s6gkrxm0000gn/T/ipykernel_83302/2682718784.py[0m in [0;36m<module>[0;34m[0m
[1;32m      1[0m [0;31m# number of  blind events[0m[0;34m[0m[0;34m[0m[0m
[0;32m----> 2[0;31m [0mnevts_bkg_roi[0m  [0;34m=[0m [0;34m([0m[0mcollpars[0m[0;34m.[0m[0mnevts_Bi_RoI[0m [0;34m,[0m [0mcollpars[0m[0;34m.[0m[0mnevts_Tl_RoI[0m[0;34m)[0m[0;34m[0m[0;34m[0m[0m
[0m[1;32m      3[0m [0munevts_bkg_roi[0m [0;34m=[0m [0;34m([0m[0mcollpars[0m[0;34m.[0m[0munevts_Bi_RoI[0m[0;34m,[0m [0mcollpars[0m[0;34m.[0m[0munevts_Tl_RoI[0m[0;34m)[0m[0;34m[0m[0;34m[0m[0m
[1;32m      4[0m [0mnbkg_roi[0m       [0;34m=[0m [0mnp[0m[0;34m.[0m[0msum[0m[0;34m([0m[0mnevts_bkg_roi[0m[0;34m)[0m[0;34m[0m[0;34m[0m[0m
[1;32m      5[0m [0munbkg_roi[0m      [0;34m=[0m [0mnp[0m[0;34m.[0m[0msqrt[0m[0;34m([0m[0mnp[0m[0;34m.[0m[0msum[0m[0;34m([0m[0;34m[[0m[0mu[0m[0;34m**[0m[0;36m2[0m [0;32mfor[0m [0mu[0m [0;32min[0m [0munevts_bkg_roi[0m[0;34m][0m[0;34m)[0m[0;34m)[0m[0;34m[0m[0;34m[0m[0m

[0;31mAttributeError[0m: module 'collpars' has no attribute 'nevts_Bi_RoI'
AttributeError: module 'collpars' has no attribute 'nevts_Bi_RoI'

