Traceback (most recent call last):
  File "/Users/hernando/opt/anaconda3/lib/python3.9/site-packages/jupyter_cache/executors/utils.py", line 51, in single_nb_execution
    executenb(
  File "/Users/hernando/opt/anaconda3/lib/python3.9/site-packages/nbclient/client.py", line 1204, in execute
    return NotebookClient(nb=nb, resources=resources, km=km, **kwargs).execute()
  File "/Users/hernando/opt/anaconda3/lib/python3.9/site-packages/nbclient/util.py", line 84, in wrapped
    return just_run(coro(*args, **kwargs))
  File "/Users/hernando/opt/anaconda3/lib/python3.9/site-packages/nbclient/util.py", line 62, in just_run
    return loop.run_until_complete(coro)
  File "/Users/hernando/opt/anaconda3/lib/python3.9/asyncio/base_events.py", line 647, in run_until_complete
    return future.result()
  File "/Users/hernando/opt/anaconda3/lib/python3.9/site-packages/nbclient/client.py", line 663, in async_execute
    await self.async_execute_cell(
  File "/Users/hernando/opt/anaconda3/lib/python3.9/site-packages/nbclient/client.py", line 965, in async_execute_cell
    await self._check_raise_for_error(cell, cell_index, exec_reply)
  File "/Users/hernando/opt/anaconda3/lib/python3.9/site-packages/nbclient/client.py", line 862, in _check_raise_for_error
    raise CellExecutionError.from_cell_and_msg(cell, exec_reply_content)
nbclient.exceptions.CellExecutionError: An error occurred while executing the following cell:
------------------
import core.pltext  as pltext   # extensions for plotting histograms
import core.hfit    as hfit     # extension to fit histograms
import core.efit    as efit     # Fit Utilites - Includes Extend Likelihood Fit with composite PDFs
import core.utils   as ut       # generic utilities
import ana.fanal    as fn       # analysis functions specific to fanal
import     collpars as collpars # collaboration specific parameters
pltext.style()
------------------

[0;31m---------------------------------------------------------------------------[0m
[0;31mModuleNotFoundError[0m                       Traceback (most recent call last)
[0;32m/var/folders/56/_pmdccc97ljb_l3v3s6gkrxm0000gn/T/ipykernel_83254/2986100431.py[0m in [0;36m<module>[0;34m[0m
[1;32m      4[0m [0;32mimport[0m [0mcore[0m[0;34m.[0m[0mutils[0m   [0;32mas[0m [0mut[0m       [0;31m# generic utilities[0m[0;34m[0m[0;34m[0m[0m
[1;32m      5[0m [0;32mimport[0m [0mana[0m[0;34m.[0m[0mfanal[0m    [0;32mas[0m [0mfn[0m       [0;31m# analysis functions specific to fanal[0m[0;34m[0m[0;34m[0m[0m
[0;32m----> 6[0;31m [0;32mimport[0m     [0mcollpars[0m [0;32mas[0m [0mcollpars[0m [0;31m# collaboration specific parameters[0m[0;34m[0m[0;34m[0m[0m
[0m[1;32m      7[0m [0mpltext[0m[0;34m.[0m[0mstyle[0m[0;34m([0m[0;34m)[0m[0;34m[0m[0;34m[0m[0m

[0;31mModuleNotFoundError[0m: No module named 'collpars'
ModuleNotFoundError: No module named 'collpars'

